Traceback (most recent call last):
  File "C:\ProgramData\Miniconda3\lib\site-packages\jupyter_cache\executors\utils.py", line 58, in single_nb_execution
    executenb(
  File "C:\ProgramData\Miniconda3\lib\site-packages\nbclient\client.py", line 1305, in execute
    return NotebookClient(nb=nb, resources=resources, km=km, **kwargs).execute()
  File "C:\ProgramData\Miniconda3\lib\site-packages\jupyter_core\utils\__init__.py", line 165, in wrapped
    return loop.run_until_complete(inner)
  File "C:\ProgramData\Miniconda3\lib\asyncio\base_events.py", line 647, in run_until_complete
    return future.result()
  File "C:\ProgramData\Miniconda3\lib\site-packages\nbclient\client.py", line 705, in async_execute
    await self.async_execute_cell(
  File "C:\ProgramData\Miniconda3\lib\site-packages\nbclient\client.py", line 1058, in async_execute_cell
    await self._check_raise_for_error(cell, cell_index, exec_reply)
  File "C:\ProgramData\Miniconda3\lib\site-packages\nbclient\client.py", line 914, in _check_raise_for_error
    raise CellExecutionError.from_cell_and_msg(cell, exec_reply_content)
nbclient.exceptions.CellExecutionError: An error occurred while executing the following cell:
------------------
<First Name> <Last Name> is <Age> years old and comes from <Country>.
------------------


[1;36m  Cell [1;32mIn[7], line 1[1;36m[0m
[1;33m    <First Name> <Last Name> is <Age> years old and comes from <Country>.[0m
[1;37m    ^[0m
[1;31mSyntaxError[0m[1;31m:[0m invalid syntax


